Workbook

Sheet Summary
C3: Month | D3: Sales | E3: Profit | F3: Profit %
C4: January | D4: =January!B33 -> 1170749 | E4: 150237 | F4: =round((E4/D4)*100, 0) -> 13
C5: February | D5: =February!B30 -> 1279534 | E5: 170358 | F5: =round((E5/D5)*100, 0) -> 13
C6: March | D6: =March!B33 -> 1575673 | E6: 396406 | F6: =round((E6/D6)*100, 0) -> 25
C7: April | D7: =April!B32 -> 2113012 | E7: 574820 | F7: =round((E7/D7)*100, 0) -> 27
C8: May | D8: =May!B33 -> 2268248 | E8: 539418 | F8: =round((E8/D8)*100, 0) -> 24
C9: June | D9: =June!B32 -> 1366798 | E9: 264290 | F9: =round((E9/D9)*100, 0) -> 19
C10: July | D10: =July!B33 -> 2173608 | E10: 508379 | F10: =round((E10/D10)*100, 0) -> 23
C11: August | D11: =August!B33 -> 2204126 | E11: 518660 | F11: =round((E11/D11)*100, 0) -> 24
C12: September | D12: =September!B32 -> 1850520 | E12: 0 | F12: =round((E12/D12)*100, 0) -> 0
C13: October | D13: 0 | E13: 0 | F13: =round((E13/D13)*100, 0) -> #DIV/0!
C14: November | D14: 0 | E14: 0 | F14: =round((E14/D14)*100, 0) -> #DIV/0!
C15: December | D15: 0 | E15: 0 | F15: =round((E15/D15)*100, 0) -> #DIV/0!
B17: Total | D17: =sum(D4:D15) -> 16002268 | E17: =sum(E4:E16) -> 3122568

Sheet January
A1: Date | B1: Sale | C1: Swiggy/Zomato | D1: Paytm | E1: Cash | F1: Expenses | G1: Handover cash | H1: Charges | I1: Total | J1: Comments | M1: Date | N1: Amount | O1: Comments | Q1: Date | R1: Amount | S1: Comments
A2: 1st | B2: 65656 | C2: 13779 | D2: 28997 | E2: =(B2-C2-D2) -> 22880 | F2: 1006 | G2: =(E2-F2) -> 21874 | H2: 79.45 | I2: =sum(C2+D2+F2+G2) -> 65656 | J2: Fine | K2: =IFERROR(__xludf.DUMMYFUNCTION("AI("""")"),"The dates with the highest sales were the 1st, 25th, and 4th.") -> The dates with the highest sales were the 1st, 25th, and 4th. | M2: 1st | N2: Fruits | O2: 661 | Q2: 15th | R2: Fruits | S2: 675
A3: 2nd | B3: 33861 | C3: 10844 | D3: 14355 | E3: =(B3-C3-D3) -> 8662 | F3: 525 | G3: =(E3-F3) -> 8137 | H3: 33.8 | I3: =sum(C3+D3+F3+G3) -> 33861 | J3: Fine | N3: Note books | O3: 160 | Q3: 16th | R3: Fruits | S3: 470
A4: 3rd | B4: 44602 | C4: 10830 | D4: 23905 | E4: =(B4-C4-D4) -> 9867 | F4: 1089 | G4: =(E4-F4) -> 8778 | H4: 73.81 | I4: =sum(C4+D4+F4+G4) -> 44602 | J4: Fine | N4: First aid medications | O4: 185 | R4: Water tanker | S4: 350
A5: 4th | B5: 57242 | C5: 10822 | D5: 33359 | E5: =(B5-C5-D5) -> 13061 | F5: 1236 | G5: =(E5-F5) -> 11825 | H5: 78.6 | I5: =sum(C5+D5+F5+G5) -> 57242 | J5: Expense difference on 100 rs | M5: 2nd | N5: Fruits | O5: 275 | Q5: 17th | R5: Fruits | S5: 535
A6: 5th | B6: 25349 | C6: 7615 | D6: 13548 | E6: =(B6-C6-D6) -> 4186 | F6: 717 | G6: =(E6-F6) -> 3469 | H6: 22 | I6: =sum(C6+D6+F6+G6) -> 25349 | J6: Fine | N6: Petrol for bibin | O6: 250 | Q6: 18th | R6: Fruits | S6: 766
A7: 6th | B7: 27536 | C7: 6435 | D7: 12844 | E7: =(B7-C7-D7) -> 8257 | F7: 972 | G7: =(E7-F7) -> 7285 | H7: 51.1 | I7: =sum(C7+D7+F7+G7) -> 27536 | J7: Fine | M7: 3rd | N7: Fruits | O7: 287 | R7: Mint | S7: 10
A8: 7th | B8: 28747 | C8: 3921 | D8: 18461 | E8: =(B8-C8-D8) -> 6365 | F8: 295 | G8: =(E8-F8) -> 6070 | H8: 9.09 | I8: =sum(C8+D8+F8+G8) -> 28747 | J8: Fine | N8: Strawberry | O8: 282 | Q8: 19th | R8: Fruits | S8: 619
A9: 8th | B9: 26471 | C9: 5305 | D9: 16190 | E9: =(B9-C9-D9) -> 4976 | F9: 272 | G9: =(E9-F9) -> 4704 | H9: 10.29 | I9: =sum(C9+D9+F9+G9) -> 26471 | J9: Fine | N9: Soldering | O9: 140 | Q9: 20th | R9: Fruits | S9: 510
A10: 9th | B10: 39563 | C10: 9259 | D10: 20549 | E10: =(B10-C10-D10) -> 9755 | F10: 920 | G10: =(E10-F10) -> 8835 | H10: 27.47 | I10: =sum(C10+D10+F10+G10) -> 39563 | J10: Fine | N10: Print out | O10: 30 | Q10: 21st | R10: Water tanker | S10: 350
A11: 10th | B11: 35940 | C11: 5819 | D11: 17974 | E11: =(B11-C11-D11) -> 12147 | F11: 4261 | G11: =(E11-F11) -> 7886 | H11: 35.79 | I11: =sum(C11+D11+F11+G11) -> 35940 | J11: Fine | N11: Water tanker | O11: 350 | R11: Fruits | S11: 260
A12: 11th | B12: 52537 | C12: 11239 | D12: 27944 | E12: =(B12-C12-D12) -> 13354 | F12: 1205 | G12: =(E12-F12) -> 12149 | H12: 80.21 | I12: =sum(C12+D12+F12+G12) -> 52537 | J12: Fine - 50k Deposit done | M12: 4th | N12: Fruits | O12: 576 | Q12: 22nd | R12: Fruits | S12: 198
A13: 12th | B13: 18372 | C13: 5504 | D13: 9675 | E13: =(B13-C13-D13) -> 3193 | F13: 1090 | G13: =(E13-F13) -> 2103 | H13: 21.32 | I13: =sum(C13+D13+F13+G13) -> 18372 | J13: Fine | N13: Fruits | O13: 410 | Q13: 23rd | R13: Fruits | S13: 279
A14: 13th | B14: 32401 | C14: 7939 | D14: 18420 | E14: =(B14-C14-D14) -> 6042 | F14: 1192 | G14: =(E14-F14) -> 4850 | H14: 13.93 | I14: =sum(C14+D14+F14+G14) -> 32401 | J14: Fine | N14: Wooden spoons | O14: 350 | R14: Strawberry | S14: 138
A15: 14th | B15: 29700 | C15: 6927 | D15: 16796 | E15: =(B15-C15-D15) -> 5977 | F15: 329 | G15: =(E15-F15) -> 5648 | H15: 11.49 | I15: =sum(C15+D15+F15+G15) -> 29700 | J15: Fine | M15: 5th | N15: Fruits | O15: 717 | R15: Mint leaves | S15: 20
A16: 15th | B16: 52708 | C16: 8026 | D16: 32216 | E16: =(B16-C16-D16) -> 12466 | F16: 675 | G16: =(E16-F16) -> 11791 | H16: 94.44 | I16: =sum(C16+D16+F16+G16) -> 52708 | J16: Fine | M16: 6th | N16: Petrol for bibin | O16: 220 | R16: Banana+Pineapple | S16: 192
A17: 16th | B17: 39557 | C17: 4891 | D17: 27187 | E17: =(B17-C17-D17) -> 7479 | F17: 820 | G17: =(E17-F17) -> 6659 | H17: 69.87 | I17: =sum(C17+D17+F17+G17) -> 39557 | J17: Fine | N17: Fruits | O17: 175 | R17: Strawberry | S17: 255
A18: 17th | B18: 53193 | C18: 12347 | D18: 28465 | E18: =(B18-C18-D18) -> 12381 | F18: 535 | G18: =(E18-F18) -> 11846 | H18: 60.81 | I18: =sum(C18+D18+F18+G18) -> 53193 | J18: Fine | N18: Fruits | O18: 577 | Q18: 24th | R18: Fruits | S18: 641
A19: 18th | B19: 57147 | C19: 16018 | D19: 26947 | E19: =(B19-C19-D19) -> 14182 | F19: 776 | G19: =(E19-F19) -> 13406 | H19: 108.62 | I19: =sum(C19+D19+F19+G19) -> 57147 | J19: Fine - 57k Deposit done | M19: 7th | N19: Strawberry | O19: 295 | R19: Thinner | S19: 50
A20: 19th | B20: 23719 | C20: 7417 | D20: 11653 | E20: =(B20-C20-D20) -> 4649 | F20: 619 | G20: =(E20-F20) -> 4030 | H20: 12.89 | I20: =sum(C20+D20+F20+G20) -> 23719 | J20: Fine | M20: 8th | N20: Fruits | O20: 272 | R20: Police | S20: 73
A21: 20th | B21: 20096 | C21: 5032 | D21: 7526 | E21: =(B21-C21-D21) -> 7538 | F21: 510 | G21: =(E21-F21) -> 7028 | H21: 0 | I21: =sum(C21+D21+F21+G21) -> 20096 | J21: Fine | M21: 9th | N21: Fruits | O21: 690 | Q21: 25th | R21: Fruits | S21: 814
A22: 21st | B22: 28154 | C22: 8639 | D22: 13962 | E22: =(B22-C22-D22) -> 5553 | F22: 610 | G22: =(E22-F22) -> 4943 | H22: 14.14 | I22: =sum(C22+D22+F22+G22) -> 28154 | J22: Fine | N22: Petrol for bibin | O22: 220 | R22: Diesel | S22: 1800
A23: 22nd | B23: 28225 | C23: 7464 | D23: 12645 | E23: =(B23-C23-D23) -> 8116 | F23: 198 | G23: =(E23-F23) -> 7918 | H23: 0 | I23: =sum(C23+D23+F23+G23) -> 28225 | J23: Fine | N23: Unisex | O23: 10 | Q23: 26th | R23: Marker | S23: 90
A24: 23rd | B24: 42353 | C24: 13311 | D24: 22625 | E24: =(B24-C24-D24) -> 6417 | F24: 884 | G24: =(E24-F24) -> 5533 | H24: 57.14 | I24: =sum(C24+D24+F24+G24) -> 42353 | J24: Fine | M24: 10th | N24: Ladder | O24: 3000 | R24: Diesel | S24: 1880
A25: 24th | B25: 40977 | C25: 6775 | D25: 23558 | E25: =(B25-C25-D25) -> 10644 | F25: 764 | G25: =(E25-F25) -> 9880 | H25: 38.38 | I25: =sum(C25+D25+F25+G25) -> 40977 | J25: Fine | N25: Fruits | O25: 560 | R25: Fruits | S25: 420
A26: 25th | B26: 59472 | C26: 13191 | D26: 30780 | E26: =(B26-C26-D26) -> 15501 | F26: 2614 | G26: =(E26-F26) -> 12887 | H26: 57.45 | I26: =sum(C26+D26+F26+G26) -> 59472 | J26: Fine | N26: Fruits | O26: 701 | R26: Electrician | S26: 400
A27: 26th | B27: 35788 | C27: 8459 | D27: 16794 | E27: =(B27-C27-D27) -> 10535 | F27: 3020 | G27: =(E27-F27) -> 7515 | H27: 62.29 | I27: =sum(C27+D27+F27+G27) -> 35788 | J27: Fine | K27: 50Rs Extra | M27: 11th | N27: Water can | O27: 900 | R27: AC Person | S27: 100
A28: 27th | B28: 31649 | C28: 8937 | D28: 14203 | E28: =(B28-C28-D28) -> 8509 | F28: 364 | G28: =(E28-F28) -> 8145 | H28: 27.29 | I28: =sum(C28+D28+F28+G28) -> 31649 | J28: Fine | N28: Fruits | O28: 305 | R28: Spirit | S28: 60
A29: 28th | B29: 24930 | C29: 9318 | D29: 10924 | E29: =(B29-C29-D29) -> 4688 | F29: 564 | G29: =(E29-F29) -> 4124 | H29: 18.27 | I29: =sum(C29+D29+F29+G29) -> 24930 | J29: Fine - 50k Deposit done | M29: 12th | N29: Water tanker | O29: 350 | R29: Socket - Bain | S29: 70
A30: 29th | B30: 31664 | C30: 7035 | D30: 14530 | E30: =(B30-C30-D30) -> 10099 | F30: 759 | G30: =(E30-F30) -> 9340 | H30: 37.88 | I30: =sum(C30+D30+F30+G30) -> 31664 | J30: Fine | N30: Fruits | O30: 704 | Q30: 27th | R30: Fruits | S30: 364
A31: 30th | B31: 33781 | C31: 5118 | D31: 16874 | E31: =(B31-C31-D31) -> 11789 | F31: 915 | G31: =(E31-F31) -> 10874 | H31: 48.73 | I31: =sum(C31+D31+F31+G31) -> 33781 | J31: Fine | M31: 13th | N31: Fruits | O31: 406 | Q31: 28th | R31: Fruits | S31: 564
A32: 31st | B32: 49359 | C32: 11932 | D32: 23128 | E32: =(B32-C32-D32) -> 14299 | F32: 304 | G32: =(E32-F32) -> 13995 | H32: 51.85 | I32: =sum(C32+D32+F32+G32) -> 49359 | J32: Fine | N32: Fruits | O32: 736 | Q32: 29th | R32: Water tanker | S32: 350
B33: =SUM(B2:B32) -> 1170749 | C33: =SUM(C2:C32) -> 270148 | D33: =SUM(D2:D32) -> 607034 | E33: =SUM(E2:E32) -> 293567 | F33: =SUM(F2:F32) -> 30040 | G33: =SUM(G2:G32) -> 263527 | H33: =SUM(H2:H32) -> 1308.4 | I33: =SUM(I2:I31) -> 1121390 | J33: =SUM(J2:J32) -> 0 | N33: Printout | O33: 50 | R33: Fruits | S33: 409
M34: 14th | N34: Markers | O34: 50 | Q34: 30th | R34: Fruits | S34: 915
N35: Sankranthi decorations and fruits | O35: 249 | Q35: 31st | R35: Fruits | S35: 304

Sheet February
A1: Date | B1: Sale | C1: Swiggy/Zomato | D1: Paytm | E1: Cash | F1: Expenses | G1: Handover cash | H1: Charges | I1: Total | J1: Comments | L1: Date | M1: Comments | N1: Amount | P1: Date | Q1: Comments | R1: Amount | T1: Date | U1: Comments | V1: Amount
A2: 1st | B2: 72466 | C2: 12370 | D2: 48582 | E2: =(B2-C2-D2) -> 11514 | F2: 1327 | G2: =(E2-F2) -> 10187 | H2: 76.32 | I2: =sum(C2+D2+F2+G2) -> 72466 | J2: Fine | L2: 1st | M2: Fruits | N2: 1327 | P2: 11th | Q2: Strawberry | R2: 240 | T2: 26th | U2: Fruits | V2: 721
A3: 2nd | B3: 30693 | C3: 7449 | D3: 14113 | E3: =(B3-C3-D3) -> 9131 | F3: 564 | G3: =(E3-F3) -> 8567 | H3: 9.18 | I3: =sum(C3+D3+F3+G3) -> 30693 | J3: Fine | L3: 2nd | M3: Fruits | N3: 544 | Q3: Blender | R3: 1000 | U3: Mint leaves | V3: 10
A4: 3rd | B4: 19891 | C4: 6936 | D4: 9320 | E4: =(B4-C4-D4) -> 3635 | F4: 1763 | G4: =(E4-F4) -> 1872 | H4: 13.61 | I4: =sum(C4+D4+F4+G4) -> 19891 | J4: Fine | M4: Unisex | N4: 20 | Q4: Fruits | R4: 1173 | U4: Petrol - Krishna | V4: 60
A5: 4th | B5: 26345 | C5: 5186 | D5: 14978 | E5: =(B5-C5-D5) -> 6181 | F5: 700 | G5: =(E5-F5) -> 5481 | H5: 30.22 | I5: =sum(C5+D5+F5+G5) -> 26345 | J5: Fine | L5: 3rd | M5: Fruits | N5: 375 | Q5: Garbage | R5: 1500 | T5: 27th | U5: Fruits | V5: 263
A6: 5th | B6: 32297 | C6: 11119 | D6: 14892 | E6: =(B6-C6-D6) -> 6286 | F6: 1215 | G6: =(E6-F6) -> 5071 | H6: 46.23 | I6: =sum(C6+D6+F6+G6) -> 32297 | J6: Fine | M6: Strawberry | N6: 138 | Q6: Change commission | R6: 20 | U6: Cleaning brush | V6: 250
A7: 6th | B7: 36888 | C7: 6730 | D7: 23547 | E7: =(B7-C7-D7) -> 6611 | F7: 1327 | G7: =(E7-F7) -> 5284 | H7: 36.41 | I7: =sum(C7+D7+F7+G7) -> 36888 | J7: Fine | M7: Watercan | N7: 930 | P7: 12th | Q7: Fruits | R7: 815 | U7: Unisex | V7: 5
A8: 7th | B8: 48954 | C8: 9104 | D8: 28869 | E8: =(B8-C8-D8) -> 10981 | F8: 4518 | G8: =(E8-F8) -> 6463 | H8: 97.02 | I8: =sum(C8+D8+F8+G8) -> 48954 | J8: Fine | M8: Perk | N8: 320 | Q8: Fruits | R8: 80 | T8: 28th | U8: Fruits | V8: 524
A9: 8th | B9: 57125 | C9: 11915 | D9: 25395 | E9: =(B9-C9-D9) -> 19815 | F9: 427 | G9: =(E9-F9) -> 19388 | H9: 31.96 | I9: =sum(C9+D9+F9+G9) -> 57125 | J9: Fine | L9: 4th | M9: Travel charges | N9: 700 | P9: 13th | Q9: Fruits | R9: 465 | U9: Cake | V9: 540
A10: 9th | B10: 39315 | C10: 12857 | D10: 13181 | E10: =(B10-C10-D10) -> 13277 | F10: 523 | G10: =(E10-F10) -> 12754 | H10: 29.03 | I10: =sum(C10+D10+F10+G10) -> 39315 | J10: Fine - Banking 52K | L10: 5th | M10: Fruits | N10: 503 | P10: 14th | Q10: Fruits | R10: 673 | U10: Jatre | V10: 1000
A11: 10th | B11: 34047 | C11: 10812 | D11: 14428 | E11: =(B11-C11-D11) -> 8807 | F11: 1536 | G11: =(E11-F11) -> 7271 | H11: 15.76 | I11: =sum(C11+D11+F11+G11) -> 34047 | J11: Fine | M11: Electrician | N11: 700 | P11: 15th | Q11: Fruits | R11: 723
A12: 11th | B12: 24238 | C12: 4900 | D12: 14024 | E12: =(B12-C12-D12) -> 5314 | F12: 3933 | G12: =(E12-F12) -> 1381 | H12: 2.76 | I12: =sum(C12+D12+F12+G12) -> 24238 | J12: Fine | M12: Mint leaves | N12: 12 | Q12: Fruits | R12: 281
A13: 12th | B13: 169502 | C13: 17983 | D13: 95244 | E13: =(B13-C13-D13) -> 56275 | F13: 895 | G13: =(E13-F13) -> 55380 | H13: 161.19 | I13: =sum(C13+D13+F13+G13) -> 169502 | J13: Fine | L13: 6th | M13: Printout | N13: 560 | P13: 16th | Q13: Fruits | R13: 805
A14: 13th | B14: 51284 | C14: 8402 | D14: 29700 | E14: =(B14-C14-D14) -> 13182 | F14: 465 | G14: =(E14-F14) -> 12717 | H14: 78.09 | I14: =sum(C14+D14+F14+G14) -> 51284 | J14: Banking 76000 | M14: Fruits | N14: 422 | Q14: Shutter repair | R14: 950
A15: 14th | B15: 76803 | C15: 17830 | D15: 47298 | E15: =(B15-C15-D15) -> 11675 | F15: 673 | G15: =(E15-F15) -> 11002 | H15: 119.1 | I15: =sum(C15+D15+F15+G15) -> 76803 | J15: Done | M15: Fruits | N15: 285 | P15: 17th | Q15: Fruits | R15: 448
A16: 15th | B16: 49244 | C16: 7661 | D16: 28700 | E16: =(B16-C16-D16) -> 12883 | F16: 1004 | G16: =(E16-F16) -> 11879 | H16: 58.31 | I16: =sum(C16+D16+F16+G16) -> 49244 | J16: Done - 311 excess, Banking 35K | M16: Strawberry | N16: 60 | Q16: Unisex | R16: 10
A17: 16th | B17: 27691 | C17: 3468 | D17: 16694 | E17: =(B17-C17-D17) -> 7529 | F17: 1755 | G17: =(E17-F17) -> 5774 | H17: 44.9 | I17: =sum(C17+D17+F17+G17) -> 27691 | J17: Fine | L17: 7th | M17: Diesel | N17: 3800 | P17: 18th | Q17: Water tanker | R17: 350
A18: 17th | B18: 33396 | C18: 7683 | D18: 18444 | E18: =(B18-C18-D18) -> 7269 | F18: 458 | G18: =(E18-F18) -> 6811 | H18: 0 | I18: =sum(C18+D18+F18+G18) -> 33396 | J18: Fine | M18: Fruits | N18: 576 | Q18: Fruits | R18: 705
A19: 18th | B19: 39118 | C19: 9646 | D19: 21387 | E19: =(B19-C19-D19) -> 8085 | F19: 1055 | G19: =(E19-F19) -> 7030 | H19: 62.64 | I19: =sum(C19+D19+F19+G19) -> 39118 | J19: Fine | M19: Fruits | N19: 142 | P19: 19th | Q19: Strawberry | R19: 59
A20: 19th | B20: 34193 | C20: 5618 | D20: 18995 | E20: =(B20-D20-C20) -> 9580 | F20: 59 | G20: =(E20-F20) -> 9521 | H20: 0 | I20: =sum(D20+C20+F20+G20) -> 34193 | J20: Fine - 30K cash received | L20: 8th | M20: Fruits | N20: 427 | P20: 20th | Q20: Fruits | R20: 472
A21: 20th | B21: 39387 | C21: 9209 | D21: 20779 | E21: =(B21-C21-D21) -> 9399 | F21: 502 | G21: =(E21-F21) -> 8897 | H21: 0 | I21: =sum(C21+D21+F21+G21) -> 39387 | J21: Fine | L21: 9th | M21: Fruits | N21: 523 | Q21: Mint leaves | R21: 10
A22: 21st | B22: 58026 | C22: 13919 | D22: 32855 | E22: =(B22-C22-D22) -> 11252 | F22: 994 | G22: =(E22-F22) -> 10258 | H22: 0 | I22: =sum(C22+D22+F22+G22) -> 58026 | J22: Fine | L22: 10th | M22: Fruits | N22: 546 | Q22: Unisex | R22: 20
A23: 22nd | B23: 73582 | C23: 19929 | D23: 37201 | E23: =(B23-C23-D23) -> 16452 | F23: 1058 | G23: =(E23-F23) -> 15394 | H23: 18.32 | I23: =sum(C23+D23+F23+G23) -> 73582 | J23: Fine - Banking 35000 | M23: Freezer transportation | N23: 600 | P23: 21st | Q23: Fruits | R23: 794
A24: 23rd | B24: 26472 | C24: 5490 | D24: 12932 | E24: =(B24-C24-D24) -> 8050 | F24: 272 | G24: =(E24-F24) -> 7778 | H24: 7.92 | I24: =sum(C24+D24+F24+G24) -> 26472 | J24: Fine | M24: Water can | N24: 25 | Q24: Wire | R24: 200
A25: 24th | B25: 30078 | C25: 8693 | D25: 15316 | E25: =(B25-C25-D25) -> 6069 | F25: 853 | G25: =(E25-F25) -> 5216 | H25: 5.31 | I25: =sum(C25+D25+F25+G25) -> 30078 | J25: Fine | M25: Water tanker | N25: 350 | P25: 22nd | Q25: Fruits | R25: 612
A26: 25th | B26: 34441 | C26: 8623 | D26: 14285 | E26: =(B26-C26-D26) -> 11533 | F26: 0 | G26: =(E26-F26) -> 11533 | H26: 0 | I26: =sum(C26+D26+F26+G26) -> 34441 | J26: Fine | M26: Mint leaves | N26: 15 | Q26: Strawberry | R26: 297
A27: 26th | B27: 28266 | C27: 6950 | D27: 11166 | E27: =(B27-C27-D27) -> 10150 | F27: 791 | G27: =(E27-F27) -> 9359 | H27: 12.77 | I27: =sum(C27+D27+F27+G27) -> 28266 | J27: Fine | Q27: Apple | R27: 149
A28: 27th | B28: 36889 | C28: 12771 | D28: 17803 | E28: =(B28-C28-D28) -> 6315 | F28: 518 | G28: =(E28-F28) -> 5797 | H28: 0 | I28: =sum(C28+D28+F28+G28) -> 36889 | J28: Fine | P28: 23rd | Q28: Fruits | R28: 272
A29: 28th | B29: 48903 | C29: 10555 | D29: 27643 | E29: =(B29-C29-D29) -> 10705 | F29: 2064 | G29: =(E29-F29) -> 8641 | H29: 0 | I29: =sum(C29+D29+F29+G29) -> 48903 | J29: Fine | P29: 24th | Q29: Fruits | R29: 853
B30: =SUM(B2:B29) -> 1279534 | C30: =SUM(C2:C29) -> 273808 | D30: =SUM(D2:D29) -> 687771 | E30: =SUM(E2:E29) -> 317955 | F30: =SUM(F2:F29) -> 31249 | G30: =SUM(G2:G29) -> 286706 | H30: =SUM(H2:H29) -> 957.05 | I30: =SUM(I2:I29) -> 1279534

Sheet March
A1: Date | B1: Sale | C1: Swiggy/Zomato | D1: Paytm | E1: Cash | F1: Expenses | G1: Handover cash | H1: Charges | I1: Total | J1: Comments | M1: Date | N1: Comments | O1: Amount | Q1: Date | R1: Comments | S1: Amount | U1: Date | V1: Comments | W1: Amount
A2: 1st | B2: 76837 | C2: 20449 | D2: 32740 | E2: =(B2-C2-D2) -> 23648 | F2: 920 | G2: =(E2-F2) -> 22728 | H2: 0 | I2: =sum(C2+D2+F2+G2) -> 76837 | J2: Fine, 70K banking done | M2: 1st | N2: Fruits | O2: 920 | Q2: 15th | R2: Diersel | S2: 3600 | U2: 27th | V2: Fruits | W2: 868
A3: 2nd | B3: 27542 | C3: 6721 | D3: 13400 | E3: =(B3-C3-D3) -> 7421 | F3: 2287 | G3: =(E3-F3) -> 5134 | H3: 0 | I3: =sum(C3+D3+F3+G3) -> 27542 | J3: Fine | M3: 2nd | N3: Fruits | O3: 682 | R3: Fruits | S3: 667 | V3: Mint leaves | W3: 10
A4: 3rd | B4: 39470 | C4: 16923 | D4: 13644 | E4: =(B4-C4-D4) -> 8903 | F4: 453 | G4: =(E4-F4) -> 8450 | H4: 0 | I4: =sum(C4+D4+F4+G4) -> 39470 | J4: Fine | N4: Garbage collector | O4: 1500 | R4: Fruits | S4: 67 | U4: 28th | V4: Fruits | W4: 837
A5: 4th | B5: 35275 | C5: 9888 | D5: 18431 | E5: =(B5-C5-D5) -> 6956 | F5: 311 | G5: =(E5-F5) -> 6645 | H5: 0 | I5: =sum(C5+D5+F5+G5) -> 35275 | J5: Fine | N5: Stationary | O5: 105 | R5: Fevicol | S5: 20 | V5: Water tanker | W5: 350
A6: 5th | B6: 31884 | C6: 5899 | D6: 18019 | E6: =(B6-C6-D6) -> 7966 | F6: 235 | G6: =(E6-F6) -> 7731 | H6: 6.67 | I6: =sum(C6+D6+F6+G6) -> 31884 | J6: Fine | M6: 3rd | N6: Fruits | O6: 453 | R6: Fevikwick | S6: 120 | V6: Spirit | W6: 70
A7: 6th | B7: 38367 | C7: 9570 | D7: 19053 | E7: =(B7-C7-D7) -> 9744 | F7: 742 | G7: =(E7-F7) -> 9002 | H7: 11.18 | I7: =sum(C7+D7+F7+G7) -> 38367 | J7: Fine | M7: 4th | N7: Fruits | O7: 311 | R7: Mseal | S7: 30 | V7: Medical Charges | W7: 3200
A8: 7th | B8: 52013 | C8: 16494 | D8: 28058 | E8: =(B8-C8-D8) -> 7461 | F8: 1112 | G8: =(E8-F8) -> 6349 | H8: 33.82 | I8: =sum(C8+D8+F8+G8) -> 52013 | J8: Fine | M8: 5th | N8: Fruits | O8: 235 | Q8: 16th | R8: Fruits | S8: 690 | U8: 29th | V8: Fruits | W8: 717
A9: 8th | B9: 82380 | C9: 21616 | D9: 41643 | E9: =(B9-C9-D9) -> 19121 | F9: 0 | G9: =(E9-F9) -> 19121 | H9: 25.38 | I9: =sum(C9+D9+F9+G9) -> 82380 | J9: Fine - 57K banking done | M9: 6th | N9: Bill book | O9: 85 | R9: Water tanker | S9: 350 | V9: Water tanker | W9: 350
A10: 9th | B10: 30975 | C10: 6087 | D10: 15752 | E10: =(B10-C10-D10) -> 9136 | F10: 2182 | G10: =(E10-F10) -> 6954 | H10: 5.12 | I10: =sum(C10+D10+F10+G10) -> 30975 | J10: Fine | N10: Carbon paper | O10: 15 | R10: RTP print out | S10: 90 | V10: Fruits | W10: 120
A11: 10th | B11: 31347 | C11: 8561 | D11: 14405 | E11: =(B11-C11-D11) -> 8381 | F11: 1598 | G11: =(E11-F11) -> 6783 | H11: 42.6 | I11: =sum(C11+D11+F11+G11) -> 31347 | J11: Fine | N11: Fruits | O11: 271 | Q11: 17th | R11: Fruits | S11: 453 | V11: Mint leaves | W11: 10
A12: 11th | B12: 32749 | C12: 6302 | D12: 16171 | E12: =(B12-C12-D12) -> 10276 | F12: 656 | G12: =(E12-F12) -> 9620 | H12: 39.83 | I12: =sum(C12+D12+F12+G12) -> 32749 | J12: Fine | N12: Mint leaves | O12: 10 | Q12: 18th | R12: Markers | S12: 50 | U12: 30th | V12: Fruits | W12: 1722
A13: 12th | B13: 34380 | C13: 5068 | D13: 18837 | E13: =(B13-C13-D13) -> 10475 | F13: 737 | G13: =(E13-F13) -> 9738 | H13: 4.74 | I13: =sum(C13+D13+F13+G13) -> 34380 | J13: Fine | N13: Fruits | O13: 361 | R13: Petrol | S13: 200
A14: 13th | B14: 35197 | C14: 9163 | D14: 17135 | E14: =(B14-C14-D14) -> 8899 | F14: 810 | G14: =(E14-F14) -> 8089 | H14: 0 | I14: =sum(C14+D14+F14+G14) -> 35197 | J14: Fine, received 89 extra | M14: 7th | N14: Fruits | O14: 572 | R14: Fruits | S14: 446
A15: 14th | B15: 52964 | C15: 11992 | D15: 29208 | E15: =(B15-C15-D15) -> 11764 | F15: 706 | G15: =(E15-F15) -> 11058 | H15: 0 | I15: =sum(C15+D15+F15+G15) -> 52964 | J15: Fine | N15: Manager | O15: 540 | Q15: 20th | R15: Fruits | S15: 1294
A16: 15th | B16: 63435 | C16: 21935 | D16: 31010 | E16: =(B16-C16-D16) -> 10490 | F16: 4504 | G16: =(E16-F16) -> 5986 | H16: 52.23 | I16: =sum(C16+D16+F16+G16) -> 63435 | J16: Fine - 59K banking done | M16: 8th | N16: Fruits | O16: 612 | Q16: 21st | R16: Fruits | S16: 45
A17: 16th | B17: 33261 | C17: 5665 | D17: 15234 | E17: =(B17-C17-D17) -> 12362 | F17: 1130 | G17: =(E17-F17) -> 11232 | H17: 68.57 | I17: =sum(C17+D17+F17+G17) -> 33261 | J17: Fine | N17: Chart lamination | O17: 100 | R17: Fruits | S17: 74
A18: 17th | B18: 26440 | C18: 5143 | D18: 17332 | E18: =(B18-C18-D18) -> 3965 | F18: 453 | G18: =(E18-F18) -> 3512 | H18: 17.9 | I18: =sum(C18+D18+F18+G18) -> 26440 | J18: Fine | M18: 9th | N18: Fruits | O18: 670 | R18: Fruits | S18: 722
A19: 18th | B19: 27409 | C19: 8091 | D19: 12485 | E19: =(B19-C19-D19) -> 6833 | F19: 696 | G19: =(E19-F19) -> 6137 | H19: 58 | I19: =sum(C19+D19+F19+G19) -> 27409 | J19: Fine | N19: Strawberry | O19: 240 | R19: Mint leaves | S19: 10
A20: 19th | B20: 52698 | C20: 7430 | D20: 33449 | E20: =(B20-C20-D20) -> 11819 | F20: 0 | G20: =(E20-F20) -> 11819 | H20: 70.05 | I20: =sum(C20+D20+F20+G20) -> 52698 | J20: Fine | N20: Mint leaves | O20: 10 | R20: Transportation | S20: 400
A21: 20th | B21: 68947 | C21: 13291 | D21: 33710 | E21: =(B21-C21-D21) -> 21946 | F21: 1294 | G21: =(E21-F21) -> 20652 | H21: 46.6 | I21: =sum(C21+D21+F21+G21) -> 68947 | J21: Fine | N21: Travel exoense | O21: 550 | R21: Food | S21: 1090
A22: 21st | B22: 106835 | C22: 22594 | D22: 59699 | E22: =(B22-C22-D22) -> 24542 | F22: 2341 | G22: =(E22-F22) -> 22201 | H22: 84.56 | I22: =sum(C22+D22+F22+G22) -> 106835 | J22: Fine | M22: 10th | N22: Electrician | O22: 1000 | Q22: 22nd | R22: Petrol | S22: 50
A23: 22nd | B23: 95873 | C23: 19320 | D23: 50675 | E23: =(B23-C23-D23) -> 25878 | F23: 1668 | G23: =(E23-F23) -> 24210 | H23: 48.19 | I23: =sum(C23+D23+F23+G23) -> 95873 | J23: Fine - 99k banking done | N23: Fruits | O23: 598 | R23: Fruits | S23: 479
A24: 23rd | B24: 46929 | C24: 11642 | D24: 22822 | E24: =(B24-C24-D24) -> 12465 | F24: 592 | G24: =(E24-F24) -> 11873 | H24: 0 | I24: =sum(C24+D24+F24+G24) -> 46929 | J24: Fine | M24: 11th | N24: Fruits | O24: 61 | R24: Fruits | S24: 596
A25: 24th | B25: 40355 | C25: 11368 | D25: 16126 | E25: =(B25-C25-D25) -> 12861 | F25: 0 | G25: =(E25-F25) -> 12861 | H25: 4.99 | I25: =sum(C25+D25+F25+G25) -> 40355 | J25: Fine | N25: Water tanker | O25: 350 | R25: Fruits | S25: 437
A26: 25th | B26: 43527 | C26: 7612 | D26: 21648 | E26: =(B26-C26-D26) -> 14267 | F26: 2339 | G26: =(E26-F26) -> 11928 | H26: 17.96 | I26: =sum(C26+D26+F26+G26) -> 43527 | J26: Fine | N26: Filter water | O26: 25 | R26: Fruits | S26: 106
A27: 26th | B27: 49449 | C27: 15225 | D27: 22575 | E27: =(B27-C27-D27) -> 11649 | F27: 703 | G27: =(E27-F27) -> 10946 | H27: 26.84 | I27: =sum(C27+D27+F27+G27) -> 49449 | J27: Fine | N27: Petrol | O27: 220 | Q27: 23rd | R27: Fruits | S27: 592
A28: 27th | B28: 51836 | C28: 7554 | D28: 31168 | E28: =(B28-C28-D28) -> 13114 | F28: 878 | G28: =(E28-F28) -> 12236 | H28: 5.49 | I28: =sum(C28+D28+F28+G28) -> 51836 | J28: Fine | M28: 12th | N28: Fruits | O28: 737 | Q28: 24th | R28: nil | S28: 0
A29: 28th | B29: 74537 | C29: 19375 | D29: 39145 | E29: =(B29-C29-D29) -> 16017 | F29: 4457 | G29: =(E29-F29) -> 11560 | H29: 50.84 | I29: =sum(C29+D29+F29+G29) -> 74537 | J29: Fine | M29: 13th | N29: Water tanker | O29: 350 | Q29: 25th | R29: Fruits | S29: 979
A30: 29th | B30: 86242 | C30: 20786 | D30: 46038 | E30: =(B30-C30-D30) -> 19418 | F30: 1197 | G30: =(E30-F30) -> 18221 | H30: 42.24 | I30: =sum(C30+D30+F30+G30) -> 86242 | J30: Fine | N30: Banana | O30: 44 | R30: Shutter | S30: 1350
A31: 30th | B31: 58628 | C31: 12760 | D31: 29870 | E31: =(B31-C31-D31) -> 15998 | F31: 1722 | G31: =(E31-F31) -> 14276 | H31: 48.61 | I31: =sum(C31+D31+F31+G31) -> 58628 | J31: Fine - 72k banking, 30k transfer | N31: Fruits | O31: 416 | R31: Unisex | S31: 10
A32: 31st | B32: 47892 | C32: 10184 | D32: 24137 | E32: =(B32-C32-D32) -> 13571 | F32: 220 | G32: =(E32-F32) -> 13351 | H32: 32.96 | I32: =sum(C32+D32+F32+G32) -> 47892 | J32: Fine | M32: 14th | N32: Electrician | O32: 200 | Q32: 26th | R32: Fruits | S32: 343
B33: =SUM(B2:B32) -> 1575673 | C33: =SUM(C2:C32) -> 374708 | D33: =SUM(D2:D29) -> 703574 | E33: =SUM(E2:E29) -> 348359 | F33: =SUM(F2:F29) -> 33804 | G33: =SUM(G2:G29) -> 314555 | H33: =SUM(H2:H29) -> 721.56 | I33: =SUM(I2:I32) -> 1575673 | N33: Fruits | O33: 396 | R33: Mint leaves | S33: 10
N34: Medicines | O34: 110 | R34: Water tanker | S34: 350

Sheet April
A1: Date | B1: Sale | C1: Swiggy | D1: Zomato | E1: Swiggy/Zomato | F1: Online Percentage | G1: Paytm | H1: Cash | I1: Expenses | J1: Handover cash | K1: Charges | L1: Total | M1: Comments | O1: Date | P1: Comments | Q1: Amount | S1: Date | T1: Comments | U1: Amount | W1: Date | X1: Comments | Y1: Amount
A2: 1st | B2: 53456 | C2: 4657 | D2: 5836 | E2: =C2+D2 -> 10493 | F2: =if((E2>0),round((E2/B2)*100, 2) , 0) -> 19.63 | G2: 30910 | H2: =(B2-E2-G2) -> 12053 | I2: 937 | J2: =sum(H2-I2) -> 11116 | K2: 19.49 | L2: =sum(C2+D2+G2+H2) -> 53456 | M2: Fine, 727 excess | O2: 1st | P2: Fruits | Q2: 937 | S2: 16th | T2: Water tanker | U2: 700 | W2: 25th | X2: Bus charge | Y2: 50
A3: 2nd | B3: 60170 | C3: 10405 | D3: 6105 | E3: =C3+D3 -> 16510 | F3: =if((E3>0),round((E3/B3)*100, 2) , 0) -> 27.44 | G3: 32632 | H3: =(B3-E3-G3) -> 11028 | I3: 0 | J3: =sum(H3-I3) -> 11028 | K3: 18.83 | L3: =sum(C3+D3+G3+H3) -> 60170 | M3: Fine, 4712(Dairy day) | O3: 2nd | Q3: 0 | T3: Transportation | U3: 200 | X3: Fruits | Y3: 1546
A4: 3rd | B4: 49163 | C4: 4762 | D4: 7107 | E4: =C4+D4 -> 11869 | F4: =if((E4>0),round((E4/B4)*100, 2) , 0) -> 24.14 | G4: 21434 | H4: =(B4-E4-G4) -> 15860 | I4: 1823 | J4: =sum(H4-I4) -> 14037 | K4: 84.93 | L4: =sum(C4+D4+G4+H4) -> 49163 | M4: 90 rs short | O4: 3rd | P4: Tanker | Q4: 350 | T4: Fruits | U4: 511 | W4: 26th | X4: Fruits | Y4: 1054
A5: 4th | B5: 68763 | C5: 3999 | D5: 6142 | E5: 10141 | F5: =if((E5>0),round((E5/B5)*100, 2) , 0) -> 14.75 | G5: 46151 | H5: =(B5-E5-G5) -> 12471 | I5: 5913 | J5: =sum(H5-I5) -> 6558 | K5: 67.5 | L5: =sum(C5+D5+G5+H5) -> 68763 | M5: 649 short | P5: Apple & Pine apple | Q5: 870 | S5: 17th | U5: 0 | X5: Fruits | Y5: 860
A6: 5th | B6: 74788 | C6: 5965 | D6: 7854 | E6: =C6+D6 -> 13819 | F6: =if((E6>0),round((E6/B6)*100, 2) , 0) -> 18.48 | G6: 42177 | H6: =(B6-E6-G6) -> 18792 | I6: 1198 | J6: =sum(H6-I6) -> 17594 | K6: 35.34 | L6: =sum(C6+D6+G6+H6) -> 74788 | M6: Fine - above 2 also settled, 80K deposited | P6: Banana | Q6: 106 | S6: 18th | T6: Fruits | U6: 1623 | W6: 27th | X6: Fruits | Y6: 749
A7: 6th | B7: 46062 | C7: 4898 | D7: 4691 | E7: 9589 | F7: =if((E7>0),round((E7/B7)*100, 2) , 0) -> 20.82 | G7: 25958 | H7: =(B7-E7-G7) -> 10515 | I7: 0 | J7: =(H7-I7) -> 10515 | K7: 5.16 | L7: =sum(C7+D7+G7+H7) -> 46062 | M7: Fine | P7: Apple & Pine apple | Q7: 497 | T7: Water tanker | U7: 350 | X7: Fruits | Y7: 742
A8: 7th | B8: 40857 | C8: 4934 | D8: 4643 | E8: =C8+D8 -> 9577 | F8: =if((E8>0),round((E8/B8)*100, 2) , 0) -> 23.44 | G8: 20128 | H8: =(B8-E8-G8) -> 11152 | I8: 552 | J8: =sum(H8-I8) -> 10600 | K8: 24.38 | L8: =sum(C8+D8+G8+H8) -> 40857 | M8: Fine | O8: 4th | P8: Waterman | Q8: 500 | S8: 19th | T8: Mango | U8: 6671 | W8: 28th | X8: Fruits | Y8: 717
A9: 8th | B9: 51191 | C9: 5502 | D9: 3691 | E9: =C9+D9 -> 9193 | F9: =if((E9>0),round((E9/B9)*100, 2) , 0) -> 17.96 | G9: 26091 | H9: =(B9-E9-G9) -> 15907 | I9: 8099 | J9: =sum(H9-I9) -> 7808 | K9: 12.88 | L9: =sum(C9+D9+G9+H9) -> 51191 | M9: Fine, extra 7041 to be given | P9: Fruits | Q9: 853 | T9: Mango | U9: 6671 | X9: Diesel transportation | Y9: 100
A10: 9th | B10: 57713 | C10: 6166 | D10: 5509 | E10: =C10+D10 -> 11675 | F10: =if((E10>0),round((E10/B10)*100, 2) , 0) -> 20.23 | G10: 31653 | H10: =(B10-E10-G10) -> 14385 | I10: 5214 | J10: =sum(H10-I10) -> 9171 | K10: 20.26 | L10: =sum(C10+D10+G10+H10) -> 57713 | M10: Fine | P10: Rubber band | Q10: 60 | T10: Transportation | U10: 100 | X10: Diesel | Y10: 1900
A11: 10th | B11: 59390 | C11: 7977 | D11: 6161 | E11: =C11+D11 -> 14138 | F11: =if((E11>0),round((E11/B11)*100, 2) , 0) -> 23.81 | G11: 31448 | H11: =(B11-E11-G11) -> 13804 | I11: 1220 | J11: =sum(H11-I11) -> 12584 | K11: 7.39 | L11: =sum(C11+D11+G11+H11) -> 59390 | M11: Fine | P11: Generator service | Q11: 4500 | T11: Fruits | U11: 920 | X11: Diesel | Y11: 1900
A12: 11th | B12: 79528 | C12: 7324 | D12: 5944 | E12: =C12+D12 -> 13268 | F12: =if((E12>0),round((E12/B12)*100, 2) , 0) -> 16.68 | G12: 43495 | H12: =(B12-E12-G12) -> 22765 | I12: 1214 | J12: =sum(H12-I12) -> 21551 | K12: 111.47 | L12: =sum(C12+D12+G12+H12) -> 79528 | M12: Fine | O12: 5th | P12: Petrol | Q12: 200 | S12: 20th | T12: Fruits | U12: 503 | X12: Diesel | Y12: 1050
A13: 12th | B13: 100062 | C13: 10099 | D13: 9885 | E13: =C13+D13 -> 19984 | F13: =if((E13>0),round((E13/B13)*100, 2) , 0) -> 19.97 | G13: 53538 | H13: =(B13-E13-G13) -> 26540 | I13: 1142 | J13: =sum(H13-I13) -> 25398 | K13: 198.68 | L13: =sum(C13+D13+G13+H13) -> 100062 | M13: Fine - 105K deposited | P13: Fruits | Q13: 998 | T13: Fruits | U13: 440 | X13: Diesel | Y13: 1900
A14: 13th | B14: 57275 | C14: 4094 | D14: 8574 | E14: =C14+D14 -> 12668 | F14: =if((E14>0),round((E14/B14)*100, 2) , 0) -> 22.12 | G14: 29364 | H14: =(B14-E14-G14) -> 15243 | I14: 7450 | J14: =sum(H14-I14) -> 7793 | K14: 75.03 | L14: =sum(C14+D14+G14+H14) -> 57275 | M14: Fine, 6671 is paid | O14: 6th | Q14: 0 | T14: Mint leaves | U14: 7 | W14: 29th | X14: Fruits | Y14: 543
A15: 14th | B15: 72314 | C15: 6432 | D15: 5341 | E15: =C15+D15 -> 11773 | F15: =if((E15>0),round((E15/B15)*100, 2) , 0) -> 16.28 | G15: 41086 | H15: =(B15-E15-G15) -> 19455 | I15: 876 | J15: =sum(H15-I15) -> 18579 | K15: 45.22 | L15: =sum(C15+D15+G15+H15) -> 72314 | M15: Fine | O15: 7th | P15: Fruits | Q15: 522 | S15: 21st | T15: Fruits | U15: 481 | X15: Fruits | Y15: 892
A16: 15th | B16: 66220 | C16: 5849 | D16: 7413 | E16: =C16+D16 -> 13262 | F16: =if((E16>0),round((E16/B16)*100, 2) , 0) -> 20.03 | G16: 35018 | H16: =(B16-E16-G16) -> 17940 | I16: 779 | J16: =sum(H16-I16) -> 17161 | K16: 67.82 | L16: =sum(C16+D16+G16+H16) -> 66220 | M16: Fine | O16: 8th | P16: Fruits | Q16: 864 | T16: Water tanker | U16: 350 | W16: 30th | X16: Fruits | Y16: 1579
A17: 16th | B17: 67326 | C17: 3871 | D17: 11672 | E17: =C17+D17 -> 15543 | F17: =if((E17>0),round((E17/B17)*100, 2) , 0) -> 23.09 | G17: 30905 | H17: =(B17-E17-G17) -> 20878 | I17: 1411 | J17: =sum(H17-I17) -> 19467 | K17: 29 | L17: =sum(C17+D17+G17+H17) -> 67326 | M17: Fine | P17: Fruits | Q17: 94 | T17: Transportation | U17: 100 | X17: Transportation(Mango pulp from Naveesh) | Y17: 100
A18: 17th | B18: 81304 | C18: 4388 | D18: 8305 | E18: =C18+D18 -> 12693 | F18: =if((E18>0),round((E18/B18)*100, 2) , 0) -> 15.61 | G18: 49847 | H18: =(B18-E18-G18) -> 18764 | I18: 500 | J18: =sum(H18-I18) -> 18264 | K18: 28.51 | L18: =sum(C18+D18+G18+H18) -> 81304 | M18: Fine, 500 in giftcard | P18: Transportation | Q18: 100 | T18: Fruits | U18: 58 | X18: Food | Y18: 1083
A19: 18th | B19: 87770 | C19: 8336 | D19: 8918 | E19: =C19+D19 -> 17254 | F19: =if((E19>0),round((E19/B19)*100, 2) , 0) -> 19.66 | G19: 53064 | H19: =(B19-E19-G19) -> 17452 | I19: 1973 | J19: =sum(H19-I19) -> 15479 | K19: 109.18 | L19: =sum(C19+D19+G19+H19) -> 87770 | M19: Fine | P19: Mango | Q19: 7041 | S19: 22nd | T19: Fruits | U19: 768
A20: 19th | B20: 104230 | C20: 7705 | D20: 16244 | E20: =C20+D20 -> 23949 | F20: =if((E20>0),round((E20/B20)*100, 2) , 0) -> 22.98 | G20: 58258 | H20: =(B20-E20-G20) -> 22023 | I20: 14362 | J20: =sum(H20-I20) -> 7661 | K20: 38.41 | L20: =sum(C20+D20+G20+H20) -> 104230 | M20: Fine, 6671 and 6671 is paid | O20: 9th | P20: Diesel | Q20: 3600 | T20: Spirit | U20: 260
A21: 20th | B21: 77309 | C21: 7648 | D21: 7048 | E21: =C21+D21 -> 14696 | F21: =if((E21>0),round((E21/B21)*100, 2) , 0) -> 19.01 | G21: 43964 | H21: =(B21-E21-G21) -> 18649 | I21: 1040 | J21: =sum(H21-I21) -> 17609 | K21: 27.54 | L21: =sum(C21+D21+G21+H21) -> 77309 | M21: Fine, 500 in gift card, 128K deposited | P21: Garbage | Q21: 1500 | T21: Transportation | U21: 250
A22: 21st | B22: 64072 | C22: 4923 | D22: 5809 | E22: =C22+D22 -> 10732 | F22: =if((E22>0),round((E22/B22)*100, 2) , 0) -> 16.75 | G22: 34868 | H22: =(B22-E22-G22) -> 18472 | I22: 989 | J22: =sum(H22-I22) -> 17483 | K22: 19.47 | L22: =sum(C22+D22+G22+H22) -> 64072 | M22: Fine | P22: Fruits | Q22: 114 | S22: 23rd | T22: Electrician | U22: 400
A23: 22nd | B23: 79319 | C23: 7591 | D23: 9572 | E23: =C23+D23 -> 17163 | F23: =if((E23>0),round((E23/B23)*100, 2) , 0) -> 21.64 | G23: 45232 | H23: =(B23-E23-G23) -> 16924 | I23: 1278 | J23: =sum(H23-I23) -> 15646 | K23: 87.37 | L23: =sum(C23+D23+G23+H23) -> 79319 | M23: Fine | O23: 10th | P23: Electrician | Q23: 200 | T23: Diesel | U23: 1800
A24: 23rd | B24: 70069 | C24: 6481 | D24: 8781 | E24: =C24+D24 -> 15262 | F24: =if((E24>0),round((E24/B24)*100, 2) , 0) -> 21.78 | G24: 36141 | H24: =(B24-E24-G24) -> 18666 | I24: 9378 | J24: =sum(H24-I24) -> 9288 | K24: 606.16 | L24: =sum(C24+D24+G24+H24) -> 70069 | M24: Fine, 5981 extra for mangoes | P24: Fruits | Q24: 1020 | T24: Fruits | U24: 847
A25: 24th | B25: 80716 | C25: 8737 | D25: 5854 | E25: =C25+D25 -> 14591 | F25: =if((E25>0),round((E25/B25)*100, 2) , 0) -> 18.08 | G25: 47687 | H25: =(B25-E25-G25) -> 18438 | I25: 7231 | J25: =sum(H25-I25) -> 11207 | K25: 7.76 | L25: =sum(C25+D25+G25+H25) -> 80716 | M25: Fine, 5751 extra for mangoes | O25: 11th | P25: Water tanker | Q25: 350 | T25: Mango | U25: 5981
A26: 25th | B26: 100733 | C26: 14250 | D26: 11283 | E26: =C26+D26 -> 25533 | F26: =if((E26>0),round((E26/B26)*100, 2) , 0) -> 25.35 | G26: 55003 | H26: =(B26-E26-G26) -> 20197 | I26: 1596 | J26: =sum(H26-I26) -> 18601 | K26: 105.02 | L26: =sum(C26+D26+G26+H26) -> 100733 | M26: Fine | P26: Fruits | Q26: 864 | T26: Water tanker | U26: 350
A27: 26th | B27: 104248 | C27: 10304 | D27: 7037 | E27: =C27+D27 -> 17341 | F27: =if((E27>0),round((E27/B27)*100, 2) , 0) -> 16.63 | G27: 59668 | H27: =(B27-E27-G27) -> 27239 | I27: 1914 | J27: =sum(H27-I27) -> 25325 | K27: 98.16 | L27: =sum(C27+D27+G27+H27) -> 104248 | M27: Fine, 99K deposited | O27: 12th | P27: Fruits | Q27: 1142 | S27: 24th | T27: Local mango | U27: 484
A28: 27th | B28: 63431 | C28: 10409 | D28: 4691 | E28: =C28+D28 -> 15100 | F28: =if((E28>0),round((E28/B28)*100, 2) , 0) -> 23.81 | G28: 32899 | H28: =(B28-E28-G28) -> 15432 | I28: 1491 | J28: =sum(H28-I28) -> 13941 | K28: 62.45 | L28: =sum(C28+D28+G28+H28) -> 63431 | M28: Fine | O28: 13th | P28: Mango | Q28: 6671 | T28: Petrol | U28: 100
A29: 28th | B29: 57388 | C29: 4647 | D29: 7146 | E29: =C29+D29 -> 11793 | F29: =if((E29>0),round((E29/B29)*100, 2) , 0) -> 20.55 | G29: 27858 | H29: =(B29-E29-G29) -> 17737 | I29: 7567 | J29: =sum(H29-I29) -> 10170 | K29: 0 | L29: =sum(C29+D29+G29+H29) -> 57388 | M29: Fine | P29: Fruits | Q29: 779 | T29: Mango | U29: 5751
A30: 29th | B30: 73813 | C30: 4315 | D30: 6915 | E30: =C30+D30 -> 11230 | F30: =if((E30>0),round((E30/B30)*100, 2) , 0) -> 15.21 | G30: 45365 | H30: =(B30-E30-G30) -> 17218 | I30: 1435 | J30: =sum(H30-I30) -> 15783 | K30: 52.71 | L30: =sum(C30+D30+G30+H30) -> 73813 | M30: Fine | O30: 14th | P30: Fruits | Q30: 676 | T30: Water tanker | U30: 350
A31: 30th | B31: 64332 | C31: 2669 | D31: 9325 | E31: =C31+D31 -> 11994 | F31: =if((E31>0),round((E31/B31)*100, 2) , 0) -> 18.64 | G31: 36047 | H31: =(B31-E31-G31) -> 16291 | I31: 2762 | J31: =sum(H31-I31) -> 13529 | K31: 32.48 | L31: =sum(C31+D31+G31+H31) -> 64332 | M31: Fine | P31: Transportation (SM) | Q31: 200 | T31: Fruits | U31: 546
B32: =SUM(B2:B31) -> 2113012 | C32: =SUM(C2:C31) -> 199337 | D32: =sum(D2:D31) -> 223496 | E32: =sum(E2:E31) -> 422833 | F32: =if((E32>0),round((E32/B32)*100, 2) , 0) -> 20.01 | G32: =SUM(G2:G29) -> 1086477 | H32: =SUM(H2:H29) -> 488781 | I32: =SUM(I2:I29) -> 87147 | J32: =SUM(J2:J29) -> 401634 | K32: =SUM(K2:K29) -> 2013.41 | L32: =SUM(L2:L31) -> 2113012 | O32: 15th | P32: Fruits | Q32: 679
P33: Transportation | Q33: 100

Sheet May
A1: Date | B1: Sale | C1: Swiggy | D1: Zomato | E1: Swiggy/Zomato | F1: Online Percentage | G1: Paytm | H1: Cash | I1: Expenses | J1: Handover cash | K1: Charges | L1: Total | M1: Comments | O1: Date | P1: Comments | Q1: Amount | S1: Date | T1: Comments | U1: Amount | W1: Date | X1: Comments | Y1: Amount
A2: 1st | B2: 104130 | C2: 7693 | D2: 12893 | E2: =sum(C2:D2) -> 20586 | F2: =if((E2>0),round((E2/B2)*100, 2) , 0) -> 19.77 | G2: 60287 | H2: =(B2-E2-G2) -> 23257 | I2: 887 | J2: =sum(H2-I2) -> 22370 | K2: 58.17 | L2: =sum(C2+D2+G2+H2) -> 104130 | M2: Fine | O2: 1st | P2: Fruits | Q2: 887 | S2: 11th | T2: Fruits | U2: 365 | W2: 26th | X2: Bulb | Y2: 1298
A3: 2nd | B3: 93787 | C3: 11841 | D3: 13716 | E3: =sum(C3:D3) -> 25557 | F3: =if((E3>0),round((E3/B3)*100, 2) , 0) -> 27.25 | G3: 59468 | H3: =(B3-E3-G3) -> 8762 | I3: 4237 | J3: =sum(H3-I3) -> 4525 | K3: 68.17 | L3: =sum(C3+D3+G3+H3) -> 93787 | M3: Fine | O3: 2nd | P3: Fruits | Q3: 179 | T3: Audit expense | U3: 100 | X3: Fruits | Y3: 752
A4: 3rd | B4: 111485 | C4: 10090 | D4: 17383 | E4: =sum(C4:D4) -> 27473 | F4: =if((E4>0),round((E4/B4)*100, 2) , 0) -> 24.64 | G4: 56299 | H4: =(B4-E4-G4) -> 27713 | I4: 1481 | J4: =sum(H4-I4) -> 26232 | K4: 35.72 | L4: =sum(C4+D4+G4+H4) -> 111485 | M4: Fine | P4: Bus charge(Mango pulp) | Q4: 100 | S4: 12th | T4: Fruits | U4: 285 | X4: Water tanker | Y4: 350
A5: 4th | B5: 70912 | C5: 5412 | D5: 9729 | E5: =sum(C5:D5) -> 15141 | F5: =if((E5>0),round((E5/B5)*100, 2) , 0) -> 21.35 | G5: 39822 | H5: =(B5-E5-G5) -> 15949 | I5: 6567 | J5: =sum(H5-I5) -> 9382 | K5: 15.25 | L5: =sum(C5+D5+G5+H5) -> 70912 | M5: Fine, 107k deposited | P5: Mango | Q5: 3064 | T5: Fruits | U5: 863 | X5: Diesel | Y5: 200
A6: 5th | B6: 48295 | C6: 8560 | D6: 6857 | E6: =sum(C6:D6) -> 15417 | F6: =if((E6>0),round((E6/B6)*100, 2) , 0) -> 31.92 | G6: 22230 | H6: =(B6-E6-G6) -> 10648 | I6: 993 | J6: =sum(H6-I6) -> 9655 | K6: 0 | L6: =sum(C6+D6+G6+H6) -> 48295 | M6: Fine | P6: Fruits | Q6: 894 | T6: Mango | U6: 1575 | W6: 27th | X6: Fruits | Y6: 1201
A7: 6th | B7: 68905 | C7: 6183 | D7: 9913 | E7: =sum(C7:D7) -> 16096 | F7: =if((E7>0),round((E7/B7)*100, 2) , 0) -> 23.36 | G7: 32205 | H7: =(B7-E7-G7) -> 20604 | I7: 7152 | J7: =sum(H7-I7) -> 13452 | K7: 0 | L7: =sum(C7+D7+G7+H7) -> 68905 | M7: Fine | O7: 3rd | P7: Fruits | Q7: 1481 | S7: 13th | T7: Mango | U7: 6000 | X7: Mango | Y7: 4180
A8: 7th | B8: 80721 | C8: 8877 | D8: 8931 | E8: =sum(C8:D8) -> 17808 | F8: =if((E8>0),round((E8/B8)*100, 2) , 0) -> 22.06 | G8: 38451 | H8: =(B8-E8-G8) -> 24462 | I8: 3451 | J8: =sum(H8-I8) -> 21011 | K8: 32.05 | L8: =sum(C8+D8+G8+H8) -> 80721 | M8: Fine | O8: 4th | P8: Fruits | Q8: 2044 | T8: Mango | U8: 975 | W8: 28th | X8: — | Y8: 0
A9: 8th | B9: 84984 | C9: 9510 | D9: 13411 | E9: =sum(C9:D9) -> 22921 | F9: =if((E9>0),round((E9/B9)*100, 2) , 0) -> 26.97 | G9: 39185 | H9: =(B9-E9-G9) -> 22878 | I9: 251 | J9: =sum(H9-I9) -> 22627 | K9: 57.19 | L9: =sum(C9+D9+G9+H9) -> 84984 | M9: Fine | P9: Carpenter | Q9: 200 | T9: Transportation | U9: 150 | W9: 29th | X9: Water tanker | Y9: 350
A10: 9th | B10: 104796 | C10: 7130 | D10: 13071 | E10: =sum(C10:D10) -> 20201 | F10: =if((E10>0),round((E10/B10)*100, 2) , 0) -> 19.28 | G10: 62586 | H10: =(B10-E10-G10) -> 22009 | I10: 5033 | J10: =sum(H10-I10) -> 16976 | K10: 66.49 | L10: =sum(C10+D10+G10+H10) -> 104796 | M10: Fine, 500 gift card | P10: Broom | Q10: 80 | S10: 14th | T10: Fruits | U10: 1680 | X10: Fruits | Y10: 558
A11: 10th | B11: 111038 | C11: 11248 | D11: 21136 | E11: =sum(C11:D11) -> 32384 | F11: =if((E11>0),round((E11/B11)*100, 2) , 0) -> 29.16 | G11: 52389 | H11: =(B11-E11-G11) -> 26265 | I11: 9109 | J11: =sum(H11-I11) -> 17156 | K11: 79.38 | L11: =sum(C11+D11+G11+H11) -> 111038 | M11: Fine | P11: Water can | Q11: 3650 | S11: 15th | T11: Cake | U11: 550 | X11: Mango | Y11: 4750
A12: 11th | B12: 63084 | C12: 7404 | D12: 8389 | E12: =sum(C12:D12) -> 15793 | F12: =if((E12>0),round((E12/B12)*100, 2) , 0) -> 25.03 | G12: 32721 | H12: =(B12-E12-G12) -> 14570 | I12: 465 | J12: =sum(H12-I12) -> 14105 | K12: 25.51 | L12: =sum(C12+D12+G12+H12) -> 63084 | M12: Fine - 134k deposited | P12: Fruits | Q12: 593 | T12: Mango | U12: 1395 | W12: 30th | X12: Fruits | Y12: 896
A13: 12th | B13: 64332 | C13: 5621 | D13: 6697 | E13: =sum(C13:D13) -> 12318 | F13: =if((E13>0),round((E13/B13)*100, 2) , 0) -> 19.15 | G13: 36329 | H13: =(B13-E13-G13) -> 15685 | I13: 2723 | J13: =sum(H13-I13) -> 12962 | K13: 12.69 | L13: =sum(C13+D13+G13+H13) -> 64332 | M13: Fine | O13: 5th | P13: Fruits | Q13: 843 | S13: 16th | T13: Fruits | U13: 1016 | X13: Diesel | Y13: 1900
A14: 13th | B14: 64109 | C14: 5032 | D14: 8518 | E14: =sum(C14:D14) -> 13550 | F14: =if((E14>0),round((E14/B14)*100, 2) , 0) -> 21.14 | G14: 32618 | H14: =(B14-E14-G14) -> 17941 | I14: 1125 | J14: =sum(H14-I14) -> 16816 | K14: 29.87 | L14: =sum(C14+D14+G14+H14) -> 64109 | M14: Fine | P14: Bus charge | Q14: 150 | S14: 17th | T14: Fruits | U14: 2504 | W14: 31st | X14: Fruits | Y14: 1012
A15: 14th | B15: 68363 | C15: 3684 | D15: 5540 | E15: =sum(C15:D15) -> 9224 | F15: =if((E15>0),round((E15/B15)*100, 2) , 0) -> 13.49 | G15: 44208 | H15: =(B15-E15-G15) -> 14931 | I15: 1630 | J15: =sum(H15-I15) -> 13301 | K15: 39.45 | L15: =sum(C15+D15+G15+H15) -> 68363 | M15: Fine | O15: 6th | P15: Mango | Q15: 6000 | T15: Blood Test | U15: 350
A16: 15th | B16: 58915 | C16: 4587 | D16: 9840 | E16: =sum(C16:D16) -> 14427 | F16: =if((E16>0),round((E16/B16)*100, 2) , 0) -> 24.49 | G16: 32179 | H16: =(B16-E16-G16) -> 12309 | I16: 1945 | J16: =sum(H16-I16) -> 10364 | K16: 2.32 | L16: =sum(C16+D16+G16+H16) -> 58915 | M16: Fine | P16: Fruits | Q16: 428 | S16: 18th | T16: Fruits | U16: 0
A17: 16th | B17: 93418 | C17: 7238 | D17: 10671 | E17: =sum(C17:D17) -> 17909 | F17: =if((E17>0),round((E17/B17)*100, 2) , 0) -> 19.17 | G17: 55251 | H17: =(B17-E17-G17) -> 20258 | I17: 1016 | J17: =sum(H17-I17) -> 19242 | K17: 119.39 | L17: =sum(C17+D17+G17+H17) -> 93418 | M17: Fine | P17: Fruits | Q17: 474 | S17: 19th | T17: Fruits | U17: 916
A18: 17th | B18: 107657 | C18: 9727 | D18: 15406 | E18: =sum(C18:D18) -> 25133 | F18: =if((E18>0),round((E18/B18)*100, 2) , 0) -> 23.35 | G18: 55819 | H18: 23851 | I18: 2874 | J18: 23851 | K18: 93.97 | L18: 107657 | M18: Fine | P18: Bus charge | Q18: 100 | T18: Bus charge (meeting) -472 | U18: 472
A19: 18th | B19: 38209 | C19: 2021 | D19: 5328 | E19: =sum(C19:D19) -> 7349 | F19: =if((E19>0),round((E19/B19)*100, 2) , 0) -> 19.23 | G19: 19715 | H19: =(B19-E19-G19) -> 11145 | I19: 0 | J19: =sum(H19-I19) -> 11145 | K19: 94.2 (Settle now at 6:20 PM) | L19: =sum(C19+D19+G19+H19) -> 38209 | M19: Fine (settled twice) | P19: Petrol - SM | Q19: 150 | T19: Petrol charge | U19: 200
A20: 19th | B20: 52881 | C20: 6710 | D20: 7707 | E20: =sum(C20:D20) -> 14417 | F20: =if((E20>0),round((E20/B20)*100, 2) , 0) -> 27.26 | G20: 22511 | H20: =(B20-E20-G20) -> 15953 | I20: 3488 | J20: =sum(H20-I20) -> 12465 | K20: 29.03 | L20: =sum(C20+D20+G20+H20) -> 52881 | M20: Fine | O20: 7th | P20: Fruits | Q20: 657 | T20: Diesel | U20: 1900
A21: 20th | B21: 61421 | C21: 3362 | D21: 9820 | E21: =sum(C21:D21) -> 13182 | F21: =if((E21>0),round((E21/B21)*100, 2) , 0) -> 21.46 | G21: 36062 | H21: =(B21-E21-G21) -> 12177 | I21: 2211 | J21: =sum(H21-I21) -> 9966 | K21: 0 | L21: =sum(C21+D21+G21+H21) -> 61421 | M21: Fine | P21: Mango | Q21: 2496 | S21: 20th | T21: Pen | U21: 60
A22: 21st | B22: 53508 | C22: 3939 | D22: 8261 | E22: =sum(C22:D22) -> 12200 | F22: =if((E22>0),round((E22/B22)*100, 2) , 0) -> 22.8 | G22: 24838 | H22: =(B22-E22-G22) -> 16470 | I22: 700 | J22: =sum(H22-I22) -> 15770 | K22: 26.73 | L22: =sum(C22+D22+G22+H22) -> 53508 | M22: Fine | P22: Greese | Q22: 50 | T22: Marker | U22: 50
A23: 22nd | B23: 62174 | C23: 5584 | D23: 7560 | E23: =sum(C23:D23) -> 13144 | F23: =if((E23>0),round((E23/B23)*100, 2) , 0) -> 21.14 | G23: 30938 | H23: =(B23-E23-G23) -> 18092 | I23: 1842 | J23: =sum(H23-I23) -> 16250 | K23: 25.66 | L23: =sum(C23+D23+G23+H23) -> 62174 | M23: Fine | P23: Fruits | Q23: 98 | T23: Fruits | U23: 2101
A24: 23rd | B24: 71400 | C24: 5356 | D24: 7046 | E24: =sum(C24:D24) -> 12402 | F24: =if((E24>0),round((E24/B24)*100, 2) , 0) -> 17.37 | G24: 43197 | H24: =(B24-E24-G24) -> 15801 | I24: 3312 | J24: =sum(H24-I24) -> 12489 | K24: 84.47 | L24: =sum(C24+D24+G24+H24) -> 71400 | M24: Fine | P24: Petrol - Fruits and naveesh | Q24: 150 | S24: 21st | T24: Water Tanker | U24: 350
A25: 24th | B25: 94686 | C25: 6005 | D25: 12026 | E25: =sum(C25:D25) -> 18031 | F25: =if((E25>0),round((E25/B25)*100, 2) , 0) -> 19.04 | G25: 56670 | H25: =(B25-E25-G25) -> 19985 | I25: 1100 | J25: =sum(H25-I25) -> 18885 | K25: 76.53 | L25: =sum(C25+D25+G25+H25) -> 94686 | M25: Fine | O25: 8th | P25: Fruits | Q25: 251 | T25: Under tank refine? | U25: 350
A26: 25th | B26: 43916 | C26: 2697 | D26: 1122 | E26: =sum(C26:D26) -> 3819 | F26: =if((E26>0),round((E26/B26)*100, 2) , 0) -> 8.7 | G26: 25133 | H26: =(B26-E26-G26) -> 14964 | I26: 0 | J26: =sum(H26-I26) -> 14964 | K26: 54.93 | L26: =sum(C26+D26+G26+H26) -> 43916 | M26: Fine | O26: 9th | P26: Gift card | Q26: 500 | S26: 22nd | T26: Fruits | U26: 590
A27: 26th | B27: 40447 | C27: 6144 | D27: 3122 | E27: =sum(C27:D27) -> 9266 | F27: =if((E27>0),round((E27/B27)*100, 2) , 0) -> 22.91 | G27: 22809 | H27: =(B27-E27-G27) -> 8372 | I27: 1302 | J27: =sum(H27-I27) -> 7070 | K27: 45.33 | L27: =sum(C27+D27+G27+H27) -> 40447 | M27: Fine | P27: Fruits | Q27: 702 | T27: Mango | U27: 1152
A28: 27th | B28: 46394 | C28: 5280 | D28: 5821 | E28: =sum(C28:D28) -> 11101 | F28: =if((E28>0),round((E28/B28)*100, 2) , 0) -> 23.93 | G28: 21866 | H28: =(B28-E28-G28) -> 13427 | I28: 5381 | J28: =sum(H28-I28) -> 8046 | K28: 48.98 | L28: =sum(C28+D28+G28+H28) -> 46394 | M28: Fine | P28: Garbage | Q28: 1500 | T28: Batteries for remote | U28: 50
A29: 28th | B29: 98251 | C29: 8188 | D29: 6426 | E29: =sum(C29:D29) -> 14614 | F29: =if((E29>0),round((E29/B29)*100, 2) , 0) -> 14.87 | G29: 65078 | H29: =(B29-E29-G29) -> 18559 | I29: 0 | J29: =sum(H29-I29) -> 18559 | K29: 68.65 | L29: =sum(C29+D29+G29+H29) -> 98251 | M29: Fine | P29: Fruits | Q29: 431 | T29: Printout and Lamination | U29: 50
A30: 29th | B30: 58440 | C30: 6042 | D30: 7043 | E30: =sum(C30:D30) -> 13085 | F30: =if((E30>0),round((E30/B30)*100, 2) , 0) -> 22.39 | G30: 33800 | H30: =(B30-E30-G30) -> 11555 | I30: 5657 | J30: =sum(H30-I30) -> 5898 | K30: 19.37 | L30: =sum(C30+D30+G30+H30) -> 58440 | M30: Fine | P30: Diesel | Q30: 1900 | S30: 23rd | T30: Water Tanker | U30: 350
A31: 30th | B31: 54364 | C31: 1992 | D31: 7405 | E31: =sum(C31:D31) -> 9397 | F31: =if((E31>0),round((E31/B31)*100, 2) , 0) -> 17.29 | G31: 31053 | H31: =(B31-E31-G31) -> 13914 | I31: 2796 | J31: =sum(H31-I31) -> 11118 | K31: 43.14 | L31: =sum(C31+D31+G31+H31) -> 54364 | M31: Fine | O31: 10th | P31: Fruits | Q31: 599 | T31: Staff Food | U31: 525
A32: 31st | B32: 93226 | C32: 12817 | D32: 15301 | E32: =sum(C32:D32) -> 28118 | F32: =if((E32>0),round((E32/B32)*100, 2) , 0) -> 30.16 | G32: 45589 | H32: =(B32-E32-G32) -> 19519 | I32: 1012 | J32: =sum(H32-I32) -> 18507 | K32: 38.74 | L32: =sum(C32+D32+G32+H32) -> 93226 | M32: Fine | P32: Fruits | Q32: 970 | T32: Fruits | U32: 915
B33: =SUM(B2:B32) -> 2268248 | C33: =SUM(C2:C32) -> 205974 | D33: =sum(D2:D32) -> 296089 | E33: =sum(E2:E31) -> 473945 | F33: =if((E33>0),round((E33/B33)*100, 2) , 0) -> 20.89 | G33: =SUM(G2:G29) -> 1120864 | H33: =SUM(H2:H29) -> 487037 | I33: =SUM(I2:I29) -> 70275 | J33: =SUM(J2:J29) -> 419636 | K33: =SUM(K2:K29) -> 1195.93 | L33: =SUM(L2:L31) -> 2175022 | P33: Food | Q33: 1280 | T33: Mango | U33: 1522
P34: Stationary | Q34: 50 | S34: 24th | T34: Fruits | U34: 1100
P35: Mango - Local | Q35: 450
P36: Mango | Q36: 5760

Sheet June
A1: Date | B1: Sale | C1: Swiggy | D1: Zomato | E1: Swiggy/Zomato | F1: Online Percentage | G1: Paytm | H1: Cash | I1: Expenses | J1: Handover cash | K1: Charges | L1: Total | M1: Comments | O1: Date | P1: Comments | Q1: Amount | S1: Date | T1: Comments | U1: Amount | W1: Date | X1: Comments | Y1: Amount | AA1: Date | AB1: Comments | AC1: Amount
A2: 1st | B2: 38041 | C2: 3454 | D2: 3494 | E2: =sum(C2:D2) -> 6948 | F2: =if((E2>0),round((E2/B2)*100, 2) , 0) -> 18.26 | G2: 23177 | H2: =(B2-E2-G2) -> 7916 | I2: 1037 | J2: =sum(H2-I2) -> 6879 | K2: 28.35 | L2: =sum(C2+D2+G2+H2) -> 38041 | M2: Fine | O2: 1st | P2: Water tanker | Q2: 450 | S2: 10th | T2: Diesel | U2: 2000 | W2: 19th | X2: Apple | Y2: 305 | AA2: 28th | AB2: Surgical spirit | AC2: 60
A3: 2nd | B3: 38323 | C3: 2912 | D3: 4031 | E3: =sum(C3:D3) -> 6943 | F3: =if((E3>0),round((E3/B3)*100, 2) , 0) -> 18.12 | G3: 22444 | H3: =(B3-E3-G3) -> 8936 | I3: 5343 | J3: =sum(H3-I3) -> 3593 | K3: 26.52 | L3: =sum(C3+D3+G3+H3) -> 38323 | M3: Fine | P3: Bill book | Q3: 100 | S3: 11th | T3: Water tanker | U3: 400 | X3: Banana | Y3: 51 | AB3: Tablet | AC3: 10
A4: 3rd | B4: 39421 | C4: 4040 | D4: 6387 | E4: =sum(C4:D4) -> 10427 | F4: =if((E4>0),round((E4/B4)*100, 2) , 0) -> 26.45 | G4: 21915 | H4: =(B4-E4-G4) -> 7079 | I4: 729 | J4: =sum(H4-I4) -> 6350 | K4: 95.75 | L4: =sum(C4+D4+G4+H4) -> 39421 | M4: Fine | P4: Petrol | Q4: 150 | S4: 12th | T4: Unisex | U4: 10 | X4: Pineapple | Y4: 152 | AB4: Apple | AC4: 241
A5: 4th | B5: 37860 | C5: 2967 | D5: 6666 | E5: =sum(C5:D5) -> 9633 | F5: =if((E5>0),round((E5/B5)*100, 2) , 0) -> 25.44 | G5: 18810 | H5: =(B5-E5-G5) -> 9417 | I5: 9025 | J5: =sum(H5-I5) -> 392 | K5: 8.78 | L5: =sum(C5+D5+G5+H5) -> 37860 | M5: Fine | P5: Fruits | Q5: 337 | T5: Apple | U5: 544 | X5: Mint | Y5: 8 | AB5: Pineapple | AC5: 180
A6: 5th | B6: 56277 | C6: 830 | D6: 5878 | E6: =sum(C6:D6) -> 6708 | F6: =if((E6>0),round((E6/B6)*100, 2) , 0) -> 11.92 | G6: 37698 | H6: =(B6-E6-G6) -> 11871 | I6: 350 | J6: =sum(H6-I6) -> 11521 | K6: 16.65 | L6: =sum(C6+D6+G6+H6) -> 56277 | M6: Fine | O6: 2nd | P6: Banana | Q6: 68 | T6: Pineapple | U6: 255 | X6: Mango | Y6: 4760 | AB6: Banana | AC6: 88
A7: 6th | B7: 59213 | C7: 5115 | D7: 10398 | E7: =sum(C7:D7) -> 15513 | F7: =if((E7>0),round((E7/B7)*100, 2) , 0) -> 26.2 | G7: 34825 | H7: =(B7-E7-G7) -> 8875 | I7: 400 | J7: =sum(H7-I7) -> 8475 | K7: 26.9 | L7: =sum(C7+D7+G7+H7) -> 59213 | M7: Fine | P7: Mint | Q7: 6 | T7: Banana | U7: 91 | X7: Petrol | Y7: 50 | AA7: 29th | AB7: Banana | AC7: 107
A8: 7th | B8: 70787 | C8: 5667 | D8: 9876 | E8: =sum(C8:D8) -> 15543 | F8: =if((E8>0),round((E8/B8)*100, 2) , 0) -> 21.96 | G8: 33324 | H8: =(B8-E8-G8) -> 21920 | I8: 2716 | J8: =sum(H8-I8) -> 19204 | K8: 0 | L8: =sum(C8+D8+G8+H8) -> 70787 | M8: Fine | P8: Apple | Q8: 275 | T8: Mint | U8: 8 | W8: 20th | X8: Apple | Y8: 361 | AB8: Mint | AC8: 8
A9: 8th | B9: 42179 | C9: 5377 | D9: 2934 | E9: =sum(C9:D9) -> 8311 | F9: =if((E9>0),round((E9/B9)*100, 2) , 0) -> 19.7 | G9: 24580 | H9: =(B9-E9-G9) -> 9288 | I9: 710 | J9: =sum(H9-I9) -> 8578 | K9: 88.84 | L9: =sum(C9+D9+G9+H9) -> 42179 | M9: Fine | P9: Pineapple | Q9: 134 | T9: Mango | U9: 4250 | X9: Pineapple | Y9: 303 | AB9: Pineapple | AC9: 275
A10: 9th | B10: 44905 | C10: 2500 | D10: 8835 | E10: =sum(C10:D10) -> 11335 | F10: =if((E10>0),round((E10/B10)*100, 2) , 0) -> 25.24 | G10: 22720 | H10: =(B10-E10-G10) -> 10850 | I10: 5386 | J10: =sum(H10-I10) -> 5464 | K10: 24.66 | L10: =sum(C10+D10+G10+H10) -> 44905 | M10: Fine | P10: Mango | Q10: 4860 | T10: Water tanker | U10: 400 | W10: 21st | X10: Pineapple | Y10: 261 | AB10: Apple | AC10: 408
A11: 10th | B11: 37837 | C11: 3431 | D11: 3435 | E11: =sum(C11:D11) -> 6866 | F11: =if((E11>0),round((E11/B11)*100, 2) , 0) -> 18.15 | G11: 19106 | H11: =(B11-E11-G11) -> 11865 | I11: 2000 | J11: =sum(H11-I11) -> 9865 | K11: 4.49 | L11: =sum(C11+D11+G11+H11) -> 37837 | M11: Fine | O11: 3rd | P11: Cell | Q11: 100 | S11: 13th | T11: area manager expense | U11: 150 | X11: Apple | Y11: 405 | AB11: Gas welding | AC11: 100
A12: 11th | B12: 29112 | C12: 4412 | D12: 1796 | E12: =sum(C12:D12) -> 6208 | F12: =if((E12>0),round((E12/B12)*100, 2) , 0) -> 21.32 | G12: 15815 | H12: =(B12-E12-G12) -> 7089 | I12: 400 | J12: =sum(H12-I12) -> 6689 | K12: 10.43 | L12: =sum(C12+D12+G12+H12) -> 29112 | M12: Fine | P12: Audit expense | Q12: 100 | T12: Meeting expense | U12: 472 | X12: Banana | Y12: 81 | AB12: Colin | AC12: 130
A13: 12th | B13: 45132 | C13: 7018 | D13: 4623 | E13: =sum(C13:D13) -> 11641 | F13: =if((E13>0),round((E13/B13)*100, 2) , 0) -> 25.79 | G13: 26785 | H13: =(B13-E13-G13) -> 6706 | I13: 5558 | J13: =sum(H13-I13) -> 1148 | K13: 22.92 | L13: =sum(C13+D13+G13+H13) -> 45132 | M13: Fine | P13: Printout | Q13: 20 | S13: 14th | T13: Apple | U13: 361 | X13: Mint | Y13: 8 | AB13: Electrician | AC13: 300
A14: 13th | B14: 63246 | C14: 4281 | D14: 6093 | E14: =sum(C14:D14) -> 10374 | F14: =if((E14>0),round((E14/B14)*100, 2) , 0) -> 16.4 | G14: 42361 | H14: =(B14-E14-G14) -> 10511 | I14: 622 | J14: =sum(H14-I14) -> 9889 | K14: 35.99 | L14: =sum(C14+D14+G14+H14) -> 63246 | M14: Fine | P14: Pineapple | Q14: 170 | T14: Banana | U14: 98 | W14: 22nd | X14: Pineapple | Y14: 349
A15: 14th | B15: 72216 | C15: 6699 | D15: 15158 | E15: =sum(C15:D15) -> 21857 | F15: =if((E15>0),round((E15/B15)*100, 2) , 0) -> 30.27 | G15: 32759 | H15: =(B15-E15-G15) -> 17600 | I15: 719 | J15: =sum(H15-I15) -> 16881 | K15: 23.38 | L15: =sum(C15+D15+G15+H15) -> 72216 | M15: Fine | P15: Apple | Q15: 339 | T15: Pineapple | U15: 252 | X15: Apple | Y15: 415
A16: 15th | B16: 35909 | C16: 4634 | D16: 3066 | E16: =sum(C16:D16) -> 7700 | F16: =if((E16>0),round((E16/B16)*100, 2) , 0) -> 21.44 | G16: 19139 | H16: =(B16-E16-G16) -> 9070 | I16: 5127 | J16: =sum(H16-I16) -> 3943 | K16: 51.5 | L16: =sum(C16+D16+G16+H16) -> 35909 | M16: Fine | O16: 4th | P16: Courier | Q16: 340 | T16: Mint | U16: 8 | X16: Banana | Y16: 78
A17: 16th | B17: 36356 | C17: 4085 | D17: 6358 | E17: =sum(C17:D17) -> 10443 | F17: =if((E17>0),round((E17/B17)*100, 2) , 0) -> 28.72 | G17: 18211 | H17: =(B17-E17-G17) -> 7702 | I17: 543 | J17: =sum(H17-I17) -> 7159 | K17: 71.92 | L17: =sum(C17+D17+G17+H17) -> 36356 | M17: Fine | P17: Diesel | Q17: 1900 | S17: 15th | T17: Pineapple | U17: 247 | X17: Mint | Y17: 8
A18: 17th | B18: 38337 | C18: 1405 | D18: 7522 | E18: =sum(C18:D18) -> 8927 | F18: =if((E18>0),round((E18/B18)*100, 2) , 0) -> 23.29 | G18: 22800 | H18: =(B18-E18-G18) -> 6610 | I18: 3559 | J18: =sum(H18-I18) -> 3051 | K18: 19.27 | L18: =sum(C18+D18+G18+H18) -> 38337 | M18: Fine | P18: Pineapple | Q18: 546 | T18: Apple | U18: 373 | W18: 23rd | X18: Pineapple | Y18: 440
A19: 18th | B19: 43195 | C19: 2698 | D19: 3921 | E19: =sum(C19:D19) -> 6619 | F19: =if((E19>0),round((E19/B19)*100, 2) , 0) -> 15.32 | G19: 25778 | H19: =(B19-E19-G19) -> 10798 | I19: 4000 | J19: =sum(H19-I19) -> 6798 | K19: 62.35 | L19: =sum(C19+D19+G19+H19) -> 43195 | M19: Fine | P19: Apple | Q19: 1039 | T19: Banana | U19: 49 | X19: Apple | Y19: 681
A20: 19th | B20: 40926 | C20: 3613 | D20: 5467 | E20: =sum(C20:D20) -> 9080 | F20: =if((E20>0),round((E20/B20)*100, 2) , 0) -> 22.19 | G20: 22939 | H20: =(B20-E20-G20) -> 8907 | I20: 5326 | J20: =sum(H20-I20) -> 3581 | K20: 41.06 | L20: =sum(C20+D20+G20+H20) -> 40926 | M20: Fine | P20: Banana | Q20: 133 | T20: Mint | U20: 8 | X20: Banana | Y20: 97
A21: 20th | B21: 55765 | C21: 3153 | D21: 5416 | E21: =sum(C21:D21) -> 8569 | F21: =if((E21>0),round((E21/B21)*100, 2) , 0) -> 15.37 | G21: 36120 | H21: =(B21-E21-G21) -> 11076 | I21: 664 | J21: =sum(H21-I21) -> 10412 | K21: 27.83 | L21: =sum(C21+D21+G21+H21) -> 55765 | M21: Fine | P21: Mint | Q21: 7 | T21: Petrol | U21: 200 | X21: Mint | Y21: 8
A22: 21st | B22: 78550 | C22: 9269 | D22: 10125 | E22: =sum(C22:D22) -> 19394 | F22: =if((E22>0),round((E22/B22)*100, 2) , 0) -> 24.69 | G22: 43515 | H22: =(B22-E22-G22) -> 15641 | I22: 755 | J22: =sum(H22-I22) -> 14886 | K22: 33.8 | L22: =sum(C22+D22+G22+H22) -> 78550 | M22: Fine | P22: Petrol | Q22: 200 | T22: Mango | U22: 4250 | X22: Mango | Y22: 1530
A23: 22nd | B23: 31266 | C23: 2013 | D23: 4998 | E23: =sum(C23:D23) -> 7011 | F23: =if((E23>0),round((E23/B23)*100, 2) , 0) -> 22.42 | G23: 16019 | H23: =(B23-E23-G23) -> 8236 | I23: 850 | J23: =sum(H23-I23) -> 7386 | K23: 2.67 | L23: =sum(C23+D23+G23+H23) -> 31266 | M23: Fine | P23: Mango | Q23: 4860 | S23: 16th | T23: Pineapple | U23: 246 | W23: 24th | X23: Bandaid | Y23: 20
A24: 23rd | B24: 27951 | C24: 2045 | D24: 4547 | E24: =sum(C24:D24) -> 6592 | F24: =if((E24>0),round((E24/B24)*100, 2) , 0) -> 23.58 | G24: 15016 | H24: =(B24-E24-G24) -> 6343 | I24: 2756 | J24: =sum(H24-I24) -> 3587 | K24: 14.19 | L24: =sum(C24+D24+G24+H24) -> 27951 | M24: Fnie | O24: 5th | P24: Water tanker | Q24: 350 | T24: Apple | U24: 297 | X24: Unisex | Y24: 10
A25: 24th | B25: 29502 | C25: 1984 | D25: 4237 | E25: =sum(C25:D25) -> 6221 | F25: =if((E25>0),round((E25/B25)*100, 2) , 0) -> 21.09 | G25: 13922 | H25: =(B25-E25-G25) -> 9359 | I25: 30 | J25: =sum(H25-I25) -> 9329 | K25: 6.19 | L25: =sum(C25+D25+G25+H25) -> 29502 | M25: Fine | O25: 6th | P25: Water tanker | Q25: 400 | S25: 17th | T25: Diesel | U25: 1900 | W25: 25th | X25: Pineapple | Y25: 288
A26: 25th | B26: 40269 | C26: 1992 | D26: 5892 | E26: =sum(C26:D26) -> 7884 | F26: =if((E26>0),round((E26/B26)*100, 2) , 0) -> 19.58 | G26: 23552 | H26: =(B26-E26-G26) -> 8833 | I26: 6223 | J26: =sum(H26-I26) -> 2610 | K26: 9.14 | L26: =sum(C26+D26+G26+H26) -> 40269 | M26: Fine | O26: 7th | P26: Diesel | Q26: 2000 | T26: Pineapple | U26: 185 | X26: Apple | Y26: 476
A27: 26th | B27: 48127 | C27: 7962 | D27: 5914 | E27: =sum(C27:D27) -> 13876 | F27: =if((E27>0),round((E27/B27)*100, 2) , 0) -> 28.83 | G27: 24941 | H27: =(B27-E27-G27) -> 9310 | I27: 979 | J27: =sum(H27-I27) -> 8331 | K27: 8.91 | L27: =sum(C27+D27+G27+H27) -> 48127 | M27: Fine | P27: Banana | Q27: 72 | T27: Apple | U27: 347 | X27: Mint | Y27: 8
A28: 27th | B28: 41677 | C28: 3105 | D28: 4459 | E28: =sum(C28:D28) -> 7564 | F28: =if((E28>0),round((E28/B28)*100, 2) , 0) -> 18.15 | G28: 22662 | H28: =(B28-E28-G28) -> 11451 | I28: 556 | J28: =sum(H28-I28) -> 10895 | K28: 20.33 | L28: =sum(C28+D28+G28+H28) -> 41677 | M28: Fine | P28: Pineapple | Q28: 123 | T28: Banana | U28: 92.8 | X28: Banana | Y28: 87
A29: 28th | B29: 70657 | C29: 5225 | D29: 9501 | E29: =sum(C29:D29) -> 14726 | F29: =if((E29>0),round((E29/B29)*100, 2) , 0) -> 20.84 | G29: 36909 | H29: =(B29-E29-G29) -> 19022 | I29: 529 | J29: =sum(H29-I29) -> 18493 | K29: 30.87 | L29: =sum(C29+D29+G29+H29) -> 70657 | M29: Fine | P29: Apple | Q29: 521 | T29: Broom | U29: 175 | X29: Washroom freshner | Y29: 64
A30: 29th | B30: 37416 | C30: 3543 | D30: 7234 | E30: =sum(C30:D30) -> 10777 | F30: =if((E30>0),round((E30/B30)*100, 2) , 0) -> 28.8 | G30: 17245 | H30: =(B30-E30-G30) -> 9394 | I30: 1328 | J30: =sum(H30-I30) -> 8066 | K30: 4.74 | L30: =sum(C30+D30+G30+H30) -> 37416 | O30: 8th | P30: Unisex | Q30: 20 | T30: Water tanker | U30: 400 | X30: Shutter repair | Y30: 5300
A31: 30th | B31: 36346 | C31: 3163 | D31: 6700 | E31: =sum(C31:D31) -> 9863 | F31: =if((E31>0),round((E31/B31)*100, 2) , 0) -> 27.14 | G31: 16842 | H31: =(B31-E31-G31) -> 9641 | I31: 0 | J31: =sum(H31-I31) -> 9641 | K31: 3.61 | L31: =sum(C31+D31+G31+H31) -> 36346 | P31: Fruits | Q31: 690 | T31: Waterman | U31: 360 | W31: 26th | X31: Pineapple | Y31: 240
